<robot name="rrp_robot"> 
  
  <!-- Materiales -->
    <material name="red">
        <color rgba="1 0 0 1"/>
    </material>
    <material name="green">
        <color rgba="0 1 0 1"/>
    </material>
    <material name="blue">
        <color rgba="0 0 1 1"/>
    </material>
    <material name="yellow">
        <color rgba="1 1 0 1"/>
    </material>
    <material name="magenta">
        <color rgba="1 0 1 1"/>
    </material>
    <material name="cyan">
        <color rgba="0 1 1 1"/>
    </material>
    <material name="black">
        <color rgba="0 0 0 1"/>
    </material>
  <!--Definició de eslabones--> 
<link name = "world_link">
</link>
<link name = "base_link">
  <visual>
      <origin xyz = "0 0 0.05" rpy = "1.57 0 0"/> 
        <geometry> 
        <box size = "0.2 0.1 0.2"/> 
     </geometry> 
        <material name = "black"> 
      </material> 
    </visual> 
</link> 
 <link name = "x_axis"> 
   <visual> 
      <origin xyz = "0 0 0" rpy = "0 0 0"/> 
    <geometry> 
      <box size = "0.4 0.05 0.05"/> 
     </geometry> 
      <material name = "red"> 
      </material> 
    </visual> 
  </link> 
<link name = "y_axis"> 
   <visual> 
      <origin xyz = "0 0 0" rpy = "0 0 0"/> 
    <geometry> 
      <box size = "0.05 0.4 0.05"/> 
     </geometry> 
      <material name = "green"> 
      </material> 
    </visual> 
  </link> 
<link name = "z_axis"> 
   <visual> 
      <origin xyz = "0 0 0" rpy = "0 0 0"/> 
    <geometry> 
      <box size = "0.05 0.05 0.4"/> 
     </geometry> 
      <material name = "blue"> 
      </material> 
    </visual> 
  </link> 



<link name = "shoulder_link"> 
   <visual> 
      <origin xyz = "0 0 0.1" rpy = "0 0 0"/> 
    <geometry> 
       <cylinder radius="0.05" length="0.3"/>
     </geometry> 
      <material name = "magenta"> 
      </material> 
    </visual> 
  </link> 
<link name = "arm_link"> 
   <visual> 
      <origin xyz = "0 0 0.1" rpy = "0 0 0"/> 
    <geometry> 
     <box size = "0.05 0.05 0.3"/>
     </geometry> 
      <material name = "yellow"> 
      </material> 
    </visual> 
  </link> 
 <link name = "arm2_link"> 
   <visual> 
      <origin xyz = "0.3 0 0.1" rpy = "0 0 0"/> 
    <geometry> 
     <box size = "0.05 0.05 0.3"/>
     </geometry> 		
      <material name = "red"> 
      </material> 
    </visual> 
  </link> 
<link name = "basep_link"> 
   <visual> 
      <origin xyz = "0.45 0 0.37" rpy = "0 0 0"/> 
    <geometry> 
       <cylinder radius="0.02" length="0.1"/>
     </geometry> 
      <material name = "green"> 
      </material> 
    </visual> 
   </link> 
<link name = "juntap_link"> 
   <visual> 
      <origin xyz = "0.45 0 0.33" rpy = "0 0 0"/> 
    <geometry> 
       <cylinder radius="0.01" length="0.1"/>
     </geometry> 
      <material name = "cyan"> 
      </material> 
    </visual>
  </link> 
  <!--Definició de juntas--> 
<joint name = "world_joint" type = "fixed"> 
  <parent link = "world_link"/> 
  <child link = "base_link"/> 
  <origin xyz = "0 0 0" rpy = "0 0 0"/> 
  <axis xyz = "0 0 1"/> 
</joint>

<joint name = "shoulder_joint" type = "revolute"> 
  <parent link = "base_link"/> 
  <child link = "shoulder_link"/> 
  <origin xyz = "0 0 0.1" rpy = "0 0 0"/> 
  <axis xyz = "0 0 1"/> 
  <limit lower="-3.14" upper="3.14" effort="50" velocity="2.0"/>
</joint>
<joint name = "x_joint" type = "fixed"> 
  <parent link = "base_link"/> 
  <child link = "x_axis"/> 
  <origin xyz = "0.2 0 0" rpy = "0 0 0"/> 
</joint>
<joint name = "y_joint" type = "fixed"> 
  <parent link = "base_link"/> 
  <child link = "y_axis"/> 
  <origin xyz = "0 0.2 0" rpy = "0 0 0"/> 
  <axis xyz = "0 0 0"/> 
</joint>

<joint name = "z_joint" type = "fixed"> 
  <parent link = "base_link"/> 
  <child link = "z_axis"/> 
  <origin xyz = "0 0 0.2" rpy = "0 0 0"/> 
  <axis xyz = "0 0 0"/> 
</joint>
<joint name = "arm_joint" type = "revolute"> 
  <parent link = "shoulder_link"/> 
  <child link = "arm_link"/> 
  <origin xyz = "0 0 0.28" rpy = "0 1.57 0"/> 
  <limit lower="-1.57" upper="1.57" effort="50" velocity="2.0"/>
  <axis xyz = "1 0 0"/> 
</joint>
<joint name = "arm2_joint" type = "revolute"> 
  <parent link = "arm_link"/> 
  <child link = "arm2_link"/> 
  <origin xyz = "-0.35 0 0.25" rpy = "0 0 0"/> 
  <limit lower="-1.57" upper="1.57" effort="50" velocity="2.0"/>
  <axis xyz = "1 0 0"/> 
</joint>
<joint name = "basep_joint" type = "fixed"> 
  <parent link = "arm2_link"/> 
  <child link = "basep_link"/> 
  <origin xyz = "0 0 0.65" rpy = "0 1.57 0"/> 
  <limit lower="-1.57" upper="1.57" effort="50" velocity="2.0"/>
  <axis xyz = "0 0 0"/> 
</joint>
<joint name = "juntap_joint" type = "prismatic"> 
  <parent link = "basep_link"/> 
  <child link = "juntap_link"/> 
  <origin xyz = "0 0 0.1" rpy = "0 0 0"/> 
  <limit lower="0" upper="0.036" effort="50" velocity="2.0"/>
  <axis xyz = "0 0 1"/> 
</joint>
</robot>